<mujoco model="model">
  <worldbody>
    <body name="scissor" pos="0.11 0.0 0.1" quat="1 0 0 0">
        <!-- Fixed body for reference -->
        <geom type="sphere" size="1.01" rgba="0.8 0.8 0.8 1"/>

        <!-- Blade A -->
        <body name="blade_a" pos="0 0 0">
        <joint name="scissor_hinge_a" type="hinge" axis="0 0 1" pos="0 0 0" range="0 1.57" damping="0.01"/>
        <geom type="capsule" fromto="0 0 0 0.15 0.05 0" size="0.01" rgba="0.2 0.2 0.8 1"/>
        <geom type="capsule" fromto="0 0 0 -0.15 -0.05 0" size="0.01" rgba="0.2 0.2 0.8 1"/>
        <site name="tip_a" pos="0.15 0.05 0" size="0.01" rgba="1 0 0 1"/>
        </body>

        <!-- Blade B -->
        <body name="blade_b" pos="0 0 0">
        <joint name="scissor_hinge_b" type="hinge" axis="0 0 1" pos="0 0 0" range="0 1.57" damping="0.01"/>
        <geom type="capsule" fromto="0 0 0 0.15 -0.05 0" size="0.01" rgba="0.8 0.2 0.2 1"/>
        <geom type="capsule" fromto="0 0 0 -0.15 0.05 0" size="0.01" rgba="0.8 0.2 0.2 1"/>
        <site name="tip_b" pos="0.15 -0.05 0" size="0.01" rgba="0 1 0 1"/>
        </body>
    </body>
  </worldbody>
</mujoco>